#VRML_SIM R2019a utf8
WorldInfo {
  info [
    "The user drives a Supervisor by the Keyboard which drives slaves robots by using an emitter device."
  ]
  title "Omniscience"
}
Viewpoint {
  orientation 0.2661234817118234 0.9494630841383421 0.16642759488763942 5.118301405492246
  position -0.33860499181337245 2.6425195443317646 -6.411754546891705
}
Background {
  skyColor [
    0.4 0.7 1
  ]
}
PointLight {
  ambientIntensity 0.4
  intensity 0.5
  location 1 3 2
  castShadows TRUE
}
PointLight {
  ambientIntensity 0.4
  intensity 0.6
  location -1 2.5 -2
}
CircleArena {
  radius 12
  floorAppearance NULL
  floorTileSize 30 30
  wallThickness 0.04
  wallHeight 0.5
}
DEF GROUND_soft_loop_train Solid {
  translation -4.172753487073635 0.09999999999999823 0.22190855541365728
  rotation 0 1 0 6.27458
  scale 2 2 2
  children [
    DEF GROUND_SHAPE Group {
      children [
        Transform {
          translation -5 0 -8
          children [
            Shape {
              appearance Appearance {
                material Material {
                  diffuseColor 1 1 1
                }
                texture ImageTexture {
                  url [
                    "textures/lightwood.jpg"
                  ]
                  repeatS FALSE
                  repeatT FALSE
                }
                textureTransform TextureTransform {
                }
              }
              geometry ElevationGrid {
                height [
                  0, 0, 0, 0, 0, 0, 0, 0, 0, 0, 0, 0, 0, 0, 0, 0, 0, 0, 0, 0, 0, 0, 0, 0, 0, 0, 0, 0, 0, 0, 0, 0, 0, 0, 0, 0, 0, 0, 0, 0, 0, 0, 0, 0, 0, 0, 0, 0, 0, 0, 0, 0, 0, 0, 0, 0, 0, 0, 0, 0, 0, 0, 0, 0, 0, 0, 0, 0, 0, 0, 0, 0, 0, 0, 0, 0, 0, 0, 0, 0, 0, 0, 0, 0, 0, 0, 0, 0, 0, 0, 0, 0, 0, 0, 0, 0, 0, 0, 0, 0
                ]
                xDimension 150
                xSpacing 0.1
                zDimension 150
                zSpacing 0.1
              }
            }
          ]
        }
        Shape {
          geometry Plane {
          }
        }
      ]
    }
  ]
  boundingObject DEF GROUND_SHAPE Group {
    children [
      Transform {
        translation -5 0 -8
        children [
          Shape {
            appearance Appearance {
              material Material {
              }
              texture ImageTexture {
                url [
                  "textures/grass.jpg"
                ]
              }
              textureTransform TextureTransform {
                scale 5 5
              }
            }
            geometry ElevationGrid {
              height [
                0, 0, 0, 0, 0, 0, 0, 0, 0, 0, 0, 0, 0, 0, 0, 0, 0, 0, 0, 0, 0, 0, 0, 0, 0, 0, 0, 0, 0, 0, 0, 0, 0, 0, 0, 0, 0, 0, 0, 0, 0, 0, 0, 0, 0, 0, 0, 0, 0, 0, 0, 0, 0, 0, 0, 0, 0, 0, 0, 0, 0, 0, 0, 0, 0, 0, 0, 0, 0, 0, 0, 0, 0, 0, 0, 0, 0, 0, 0, 0, 0, 0, 0, 0, 0, 0, 0, 0, 0, 0, 0, 0, 0, 0, 0, 0, 0, 0, 0, 0
              ]
              xDimension 150
              xSpacing 0.1
              zDimension 150
              zSpacing 0.1
            }
          }
        ]
      }
      Shape {
        appearance Appearance {
          material Material {
          }
          texture ImageTexture {
            url [
              "textures/grass.png"
            ]
          }
          textureTransform TextureTransform {
            scale 10 10
          }
        }
        geometry Plane {
        }
      }
    ]
  }
}
WoodenBox {
  translation 7.67284036632443 0.2399999999999991 -5.67090837232031
  rotation 0 1 0 4.96782
  name "wooden box(37)"
  size 0.5 0.7 0.5
}
WoodenBox {
  translation 3.646942763911464 0.2399999999999991 -9.044088314337461
  rotation 0 1 0 4.96782
  name "wooden box(36)"
  size 0.5 0.7 0.5
}
WoodenBox {
  translation 6.172355717015701 0.23999999999999644 -2.8026553096712314
  rotation 0 1 0 4.96782
  name "wooden box(34)"
  size 0.5 0.7 0.5
}
WoodenBox {
  translation 1.4116317954599316 0.2399999999999991 -6.060586786452088
  rotation 0 1 0 4.96782
  name "wooden box(33)"
  size 0.5 0.7 0.5
}
WoodenBox {
  translation 5.8762923743821665 0.2100000000000005 7.328338468963857
  rotation 0 1 0 0.5
  name "wooden box(31)"
}
WoodenBox {
  translation 7.917484974759871 0.20999999999999916 7.369492080154232
  rotation 0 1 0 0.5
  name "wooden box(30)"
}
WoodenBox {
  translation -1.2276556393174864 0.23999999999999644 -0.37541954167503366
  rotation 0 1 0 4.96782
  name "wooden box(28)"
  size 0.5 0.7 0.5
}
WoodenBox {
  translation 3.8291296042732488 0.20999999999999916 7.641845250973484
  rotation 0 1 0 0.5
  name "wooden box(27)"
}
WoodenBox {
  translation -0.4290876359277238 0.25000000000000255 4.967203581404885
  rotation 0 1 0 5.36782
  name "wooden box(25)"
  size 0.5 0.5 0.5
}
WoodenBox {
  translation -6.214794125395377 0.2499999999999999 -5.580575236709001
  rotation 0 1 0 5.36782
  name "wooden box(22)"
  size 0.5 0.5 0.5
}
WoodenBox {
  translation -3.2497074510420227 0.2499999999999999 -2.019112804866305
  rotation 0 1 0 5.36782
  name "wooden box(21)"
  size 0.5 0.5 0.5
}
WoodenBox {
  translation -1.9480858878919227 0.24999999999999944 1.8679373814376097
  rotation 0 1 0 5.36782
  name "wooden box(19)"
  size 0.5 0.5 0.5
}
WoodenBox {
  translation -4.827796494985186 0.2500000000000008 8.2881492957214
  rotation 0 1 0 5.36782
  name "wooden box(20)"
  size 0.5 0.5 0.5
}
WoodenBox {
  translation -5.836100946298549 0.24999999999999634 -0.6831459847280257
  rotation 0 1 0 5.36782
  name "wooden box(18)"
  size 0.5 0.5 0.5
}
WoodenBox {
  translation -6.517601715693285 0.2399999999999991 5.411912437046221
  rotation 0 1 0 4.96782
  name "wooden box(16)"
  size 0.5 0.7 0.5
}
WoodenBox {
  translation -3.8472172848813218 0.23999999999999644 0.27677855408659724
  rotation 0 1 0 4.96782
  name "wooden box(15)"
  size 0.5 0.7 0.5
}
WoodenBox {
  translation -4.775819422040458 0.23999999999999644 2.366786043876729
  rotation 0 1 0 4.96782
  name "wooden box(29)"
  size 0.5 0.7 0.5
}
WoodenBox {
  translation -9.205815658777631 0.2399999999999991 0.05026340134849905
  rotation 0 1 0 4.96782
  name "wooden box(14)"
  size 0.5 0.7 0.5
}
WoodenBox {
  translation 1.1182103731550639 0.24 -8.706603293844104
  rotation 0 1 0 4.96782
  name "wooden box(9)"
  size 0.5 0.7 0.5
}
WoodenBox {
  translation 5.668581100059222 0.24 -5.825614212630018
  rotation 0 1 0 4.96782
  name "wooden box(10)"
  size 0.5 0.7 0.5
}
WoodenBox {
  translation 8.639328463323327 0.23999999999999821 -3.7894134738892893
  rotation 0 1 0 4.96782
  name "wooden box(35)"
  size 0.5 0.7 0.5
}
WoodenBox {
  translation 7.240906911424839 0.24 -8.09072415471637
  rotation 0 1 0 4.96782
  name "wooden box(32)"
  size 0.5 0.7 0.5
}
WoodenBox {
  translation 4.225323505310237 0.2399999999999991 -0.8487335458116387
  rotation 0 1 0 4.96782
  name "wooden box(11)"
  size 0.5 0.7 0.5
}
WoodenBox {
  translation -3.037124166546038 0.24 -8.769986062841241
  rotation 0 1 0 4.96782
  name "wooden box(12)"
  size 0.5 0.7 0.5
}
WoodenBox {
  translation -8.409477172759242 0.2399999999999991 -3.6322273330992507
  rotation 0 1 0 4.96782
  name "wooden box(13)"
  size 0.5 0.7 0.5
}
WoodenBox {
  translation -0.013273159988057337 0.049999999999999115 10.733726948994722
  rotation 0 1 0 5.36782
  name "wooden box(8)"
  size 0.5 0.7999999999999999 0.5
}
WoodenBox {
  translation 10.715055449887977 0.1800000000000018 -1.4128225297138886
  rotation 0 1 0 0.5
  name "wooden box(6)"
  size 0.6 0.7 0.6
}
WoodenBox {
  translation 2.3639511992004003 0.25000000000000255 2.039817260207233
  rotation 0 1 0 5.36782
  name "wooden box(5)"
  size 0.5 0.5 0.5
}
WoodenBox {
  translation 2.99087920124361 0.25000000000000255 4.84492976243544
  rotation 0 1 0 5.36782
  name "wooden box(24)"
  size 0.5 0.5 0.5
}
WoodenBox {
  translation 0.17508745943484216 0.2499999999999999 3.0130943592975203
  rotation 0 1 0 5.36782
  name "wooden box(23)"
  size 0.5 0.5 0.5
}
WoodenBox {
  translation -8.577679357445792 0.2499999999999999 3.556141157969475
  rotation 0 1 0 5.36782
  name "wooden box(17)"
  size 0.5 0.5 0.5
}
WoodenBox {
  translation 1.115848630408005 0.20999999999999916 7.3248761052404525
  rotation 0 1 0 0.5
}
WoodenBox {
  translation 8.930829610180233 0.05 3.4912020044936956
  rotation 0 1 0 0.5
  name "wooden box(7)"
  size 0.7000000000000001 0.9 0.6
}
WoodenBox {
  translation 5.86866135442544 0.05 1.4162958770889982
  rotation 0 1 0 0.5
  name "wooden box(26)"
  size 0.7000000000000001 0.9 0.6
}
WoodenBox {
  translation -0.7392303127563966 0.24 -5.026819177373328
  rotation 0 1 0 4.96782
  name "wooden box(1)"
  size 0.5 0.7 0.5
}
WoodenBox {
  translation 2.0653793085326346 0.2800000000000045 -3.7290080658300755
  rotation 0 1 0 5.36782
  name "wooden box(2)"
  size 0.6 0.7 0.5
}
WoodenBox {
  translation -2.4306915649777068 0.05000000000000178 -4.075364453241324
  rotation 0 1 0 5.36782
  name "wooden box(3)"
  size 0.7 1.1 0.5
}
WoodenBox {
  translation 0.29468586408535213 0.049999999999999115 -1.3382314345201558
  rotation 0 1 0 5.36782
  name "wooden box(4)"
  size 0.5 0.9 0.5
}
Robot {
  children [
    Emitter {
    }
  ]
  name "Driver"
  controller "supervisor"
  supervisor TRUE
}
DEF ROBOT1 Robot {
  translation -9.471682566280203 0.0888583818474935 -6.095575517567996
  rotation -0.0011434467355150052 -0.9999991406200318 0.0006413179871919954 -2.5430065154539654
  scale 5 5 5
  children [
    DEF MAIN_BODY Transform {
      translation 0 0.0415 0
      children [
        Shape {
          appearance Appearance {
            material Material {
              diffuseColor 0.0820075 0.364731 0.8
            }
          }
          geometry DEF BODY Cylinder {
            height 0.08
            radius 0.045
          }
        }
      ]
    }
    HingeJoint {
      jointParameters HingeJointParameters {
        position 53345.31567680182
        axis -1 0 0
        anchor 0 0.025 0
      }
      device [
        RotationalMotor {
          name "left wheel motor"
        }
        PositionSensor {
          name "left wheel sensor"
        }
      ]
      endPoint DEF LEFT_WHEEL Solid {
        translation -0.04502482423046902 0.0250501690091958 -0.00015412531622111932
        rotation -0.9999945557257177 -0.003290428221766824 0.00024819557196296206 5.9282003810341966
        children [
          DEF WHEEL Transform {
            rotation 0 0 1 1.57
            children [
              Shape {
                appearance Appearance {
                  material Material {
                    diffuseColor 1 0 0
                  }
                }
                geometry Cylinder {
                  height 0.01
                  radius 0.025
                }
              }
            ]
          }
        ]
        name "left wheel"
        boundingObject DEF WHEEL Transform {
          rotation 0 0 1 1.57
          children [
            Shape {
              appearance Appearance {
                material Material {
                  diffuseColor 1 0 0
                }
              }
              geometry Cylinder {
                height 0.01
                radius 0.025
              }
            }
          ]
        }
        physics DEF PHYSICS_WHEEL Physics {
          density -1
          mass 0.05
        }
        linearVelocity -0.06596392393135901 -0.00029002232074454656 0.09621966492511282
        angularVelocity 0.7729645655004883 0.03465268659568057 0.5294373121840956
      }
    }
    HingeJoint {
      jointParameters HingeJointParameters {
        position 50147.868254184796
        axis -1 0 0
        anchor 0 0.025 0
      }
      device [
        RotationalMotor {
          name "right wheel motor"
        }
        PositionSensor {
          name "right wheel sensor"
        }
      ]
      endPoint DEF RIGHT_WHEEL Solid {
        translation 0.04497654819629171 0.024832488862958243 -3.646056233342434e-05
        rotation -0.9999992516926333 0.0011231875466874827 -0.0004848338977967441 1.241354665479429
        children [
          DEF WHEEL Transform {
            rotation 0 0 1 1.57
            children [
              Shape {
                appearance Appearance {
                  material Material {
                    diffuseColor 1 0 0
                  }
                }
                geometry Cylinder {
                  height 0.01
                  radius 0.025
                }
              }
            ]
          }
        ]
        name "right wheel"
        boundingObject USE WHEEL
        physics DEF PHYSICS_WHEEL Physics {
          density -1
          mass 0.05
        }
        linearVelocity -0.07477323758634263 -0.00016723609410007427 0.10907391174109696
        angularVelocity 0.8771538233164848 0.03429628452169992 0.6005193102121423
      }
    }
    DEF LEFT_EYE DistanceSensor {
      translation -0.02 0.063 -0.042
      rotation 0 1 0 2.07
      children [
        DEF INFRARED Transform {
          rotation 0 0 1 1.57
          children [
            Shape {
              appearance Appearance {
                material Material {
                  diffuseColor 0.975691 0.981481 0.0252992
                }
              }
              geometry Cylinder {
                height 0.004
                radius 0.008
              }
            }
          ]
        }
      ]
      name "ds0"
      lookupTable [
        0 1024 0
        0.05 1024 0
        0.15 0 0
      ]
      numberOfRays 2
      aperture 1
    }
    DEF RIGHT_EYE DistanceSensor {
      translation 0.02 0.063 -0.042
      rotation 0 1 0 1.07
      children [
        DEF INFRARED Transform {
          rotation 0 0 1 1.57
          children [
            Shape {
              appearance Appearance {
                material Material {
                  diffuseColor 0.975691 0.981481 0.0252992
                }
              }
              geometry Cylinder {
                height 0.004
                radius 0.008
              }
            }
          ]
        }
      ]
      name "ds1"
      lookupTable [
        0 1024 0
        0.05 1024 0
        0.15 0 0
      ]
      numberOfRays 2
      aperture 1
    }
    Receiver {
    }
  ]
  name "robot1"
  boundingObject DEF MYBOT_BOUNDING Transform {
    translation 0 0.0415 0
    children [
      DEF BODY Cylinder {
        height 0.08
        radius 0.045
      }
    ]
  }
  physics DEF MYBOT_PHYSICS Physics {
    density -1
    mass 0.5
  }
  controller "slave"
  linearVelocity -0.0706396497290305 0.00022957028673906954 0.1028751184531468
  angularVelocity -0.00036814922801266454 0.036217595302345605 0.0007530707984168337
}
DEF PIONEER_3AT Pioneer3at {
  hidden position_0_1 14005.284854334357
  hidden position_0_2 14725.821165409916
  hidden position_0_3 14048.628779859013
  hidden position_0_4 14646.627036492764
  hidden position_1_0 -9.123098943911731e-15
  hidden translation_11 -0.19700057685367156 -8.455511380722506e-07 0.13308732132119117
  hidden rotation_11 -0.9999999998569746 -5.904992544394864e-06 -1.584871838803739e-05 3.0501035241660994
  hidden translation_12 0.19707807039692504 8.471872908081735e-05 0.1330636496208037
  hidden rotation_12 0.9999999996746244 -5.629836094057159e-06 -2.488083607077388e-05 4.976719242616337
  hidden translation_13 -0.19699870139512043 6.661342302938823e-05 -0.13306839705132922
  hidden rotation_13 0.9999999995577725 2.7890893291361385e-05 1.0322464793539821e-05 4.965526512903054
  hidden translation_14 0.19691761249833206 5.764775359323691e-05 -0.13311828142992393
  hidden rotation_14 -0.9999999999631897 8.013071725896496e-06 -3.0677811176949415e-06 4.023226683777317
  translation 2.765037269677205 0.20854642130772721 -7.95439033318115
  rotation 0.0006397979267166783 0.999999275034974 0.0010200922210274754 -1.925143447940023
  name "PIONEER_3AT"
  controller "ctrlKinect"
  supervisor TRUE
  extensionSlot [
    Kinect {
      translation 0 1 0
    }
    InertialUnit {
      translation 0 0.18 -0.21500000023974483
      rotation 0 -1 0 4.712389004359173
      children [
        Shape {
          appearance Appearance {
            material Material {
              diffuseColor 1 1 0
            }
            texture ImageTexture {
              url [
                "textures/imu.png"
              ]
            }
          }
          geometry Box {
            size 0.04 0.04 0.04
          }
        }
      ]
    }
    DEF EXTENSION_SLOT Group {
      children [
        DEF Kinect_Motor HingeJoint {
          position -6.41967
        }
      ]
    }
    TouchSensor {
      translation 0.000668100391624904 0.09390239508517903 -0.2571104373079538
      rotation -0.9996617951201874 -0.01285660033834981 -0.022605379997347196 0.181014625596678
      children [
        Shape {
          appearance Appearance {
            material Material {
              diffuseColor 1 0.5 0
              shininess 1
            }
          }
          geometry DEF BUMPER Box {
            size 0.48 0.02 0.01
          }
        }
      ]
      name "bumper"
      boundingObject USE BUMPER
      physics Physics {
        density 10000
      }
      locked TRUE
      linearVelocity 3.325000282500208e-07 4.707490011846006e-06 -1.1725214178902772e-06
      angularVelocity -5.606175005307731e-06 2.8618143344475053e-08 -2.037407180362975e-06
    }
    DEF MobileRobot_Emitter Emitter {
      name "MobileRobot_Emitter"
    }
    DEF MobileRobot_Receiver Receiver {
      name "MobileRobot_Receiver"
      channel 1
    }
    SickLms291 {
      translation 0 0.22999999999999998 0
    }
    Pen {
      translation 0 0.001 0
      children [
        Transform {
          translation 0 0.07 0
          children [
            Shape {
              appearance Appearance {
                material Material {
                  diffuseColor 1 0.692371 0
                  shininess 0.5
                  specularColor 0.98 0.570712 0.0103341
                }
              }
              geometry Cylinder {
                height 0.14
                radius 0.004
              }
            }
          ]
        }
      ]
      inkColor 1 0 0
      inkDensity 1
      leadSize 0.19999999999999998
    }
  ]
}
